# coding:utf-8
import itertools
import logging
import random
import re
import sys
import threading
import unittest.mock

import pytest

import backoff
from tests.common import _save_target


@pytest.fixture
def patch_time(monkeypatch):
    now = 0.0
    log = []

    def sleep(x):
        nonlocal now
        now += float(x)
        log.append(x)

    def monotonic():
        return now

    monkeypatch.setattr('time.sleep', sleep)
    monkeypatch.setattr('time.monotonic', monotonic)

    return log


def test_on_predicate(patch_time):

    @backoff.on_predicate(backoff.expo)
    def return_true(log, n):
        val = (len(log) == n - 1)
        log.append(val)
        return val

    log = []
    ret = return_true(log, 3)
    assert ret is True
    assert 3 == len(log)


def test_on_predicate_max_tries(patch_time):

    @backoff.on_predicate(backoff.expo, jitter=None, max_tries=3)
    def return_true(log, n):
        val = (len(log) == n)
        log.append(val)
        return val

    log = []
    ret = return_true(log, 10)
    assert ret is False
    assert 3 == len(log)


def test_on_predicate_max_time(patch_time):

    def giveup(details):
        # Should be sleeps of 1, 2, 4 then 3 seconds, last one cut short.
        # That's four sleeps in between five tries.
        assert details['tries'] == 5
        assert details['elapsed'] == 10

    @backoff.on_predicate(backoff.expo, jitter=None, max_time=10,
                          on_giveup=giveup)
    def return_true(log, n):
        val = (len(log) == n)
        log.append(val)
        return val

    log = []
    ret = return_true(log, 10)
    assert ret is False
    assert len(log) == 5


def test_on_exception(patch_time):

    @backoff.on_exception(backoff.expo, KeyError)
    def keyerror_then_true(log, n):
        if len(log) == n:
            return True
        e = KeyError()
        log.append(e)
        raise e

    log = []
    assert keyerror_then_true(log, 3) is True
    assert 3 == len(log)


def test_on_exception_tuple(patch_time):

    @backoff.on_exception(backoff.expo, (KeyError, ValueError))
    def keyerror_valueerror_then_true(log):
        if len(log) == 2:
            return True
        if len(log) == 0:
            e = KeyError()
        if len(log) == 1:
            e = ValueError()
        log.append(e)
        raise e

    log = []
    assert keyerror_valueerror_then_true(log) is True
    assert 2 == len(log)
    assert isinstance(log[0], KeyError)
    assert isinstance(log[1], ValueError)


def test_on_exception_max_tries(patch_time):

    @backoff.on_exception(backoff.expo, KeyError, jitter=None, max_tries=3)
    def keyerror_then_true(log, n, foo=None):
        if len(log) == n:
            return True
        e = KeyError()
        log.append(e)
        raise e

    log = []
    with pytest.raises(KeyError):
        keyerror_then_true(log, 10, foo="bar")

    assert 3 == len(log)


def test_on_exception_constant_iterable(patch_time):

    backoffs = []
    giveups = []
    successes = []

    @backoff.on_exception(
        backoff.constant,
        KeyError,
        interval=(1, 2, 3),
        on_backoff=backoffs.append,
        on_giveup=giveups.append,
        on_success=successes.append,
    )
    def endless_exceptions():
        raise KeyError('foo')

    with pytest.raises(KeyError):
        endless_exceptions()

    assert len(backoffs) == 3
    assert len(giveups) == 1
    assert len(successes) == 0


def test_on_exception_success_random_jitter(patch_time):

    backoffs, giveups, successes = [], [], []

    @backoff.on_exception(backoff.expo,
                          Exception,
                          on_success=successes.append,
                          on_backoff=backoffs.append,
                          on_giveup=giveups.append,
                          jitter=backoff.random_jitter,
                          factor=0.5)
    @_save_target
    def succeeder(*args, **kwargs):
        # succeed after we've backed off twice
        if len(backoffs) < 2:
            raise ValueError("catch me")

    succeeder(1, 2, 3, foo=1, bar=2)

    # we try 3 times, backing off twice before succeeding
    assert len(successes) == 1
    assert len(backoffs) == 2
    assert len(giveups) == 0

    for i in range(2):
        details = backoffs[i]
        assert details['wait'] >= 0.5 * 2 ** i


def test_on_exception_success_full_jitter(patch_time):

    backoffs, giveups, successes = [], [], []

    @backoff.on_exception(backoff.expo,
                          Exception,
                          on_success=successes.append,
                          on_backoff=backoffs.append,
                          on_giveup=giveups.append,
                          jitter=backoff.full_jitter,
                          factor=0.5)
    @_save_target
    def succeeder(*args, **kwargs):
        # succeed after we've backed off twice
        if len(backoffs) < 2:
            raise ValueError("catch me")

    succeeder(1, 2, 3, foo=1, bar=2)

    # we try 3 times, backing off twice before succeeding
    assert len(successes) == 1
    assert len(backoffs) == 2
    assert len(giveups) == 0

    for i in range(2):
        details = backoffs[i]
        assert details['wait'] <= 0.5 * 2 ** i


def test_on_exception_success():
    backoffs, giveups, successes = [], [], []

    @backoff.on_exception(backoff.constant,
                          Exception,
                          on_success=successes.append,
                          on_backoff=backoffs.append,
                          on_giveup=giveups.append,
                          jitter=None,
                          interval=0)
    @_save_target
    def succeeder(*args, **kwargs):
        # succeed after we've backed off twice
        if len(backoffs) < 2:
            raise ValueError("catch me")

    succeeder(1, 2, 3, foo=1, bar=2)

    # we try 3 times, backing off twice before succeeding
    assert len(successes) == 1
    assert len(backoffs) == 2
    assert len(giveups) == 0

    for i in range(2):
        details = backoffs[i]
        elapsed = details.pop('elapsed')
        assert isinstance(elapsed, float)
        assert details == {'args': (1, 2, 3),
                           'kwargs': {'foo': 1, 'bar': 2},
                           'target': succeeder._target,
                           'tries': i + 1,
                           'wait': 0}

    details = successes[0]
    elapsed = details.pop('elapsed')
    assert isinstance(elapsed, float)
    assert details == {'args': (1, 2, 3),
                       'kwargs': {'foo': 1, 'bar': 2},
                       'target': succeeder._target,
                       'tries': 3}


@pytest.mark.parametrize('raise_on_giveup', [True, False])
def test_on_exception_giveup(raise_on_giveup):
    backoffs, giveups, successes = [], [], []

    @backoff.on_exception(backoff.constant,
                          ValueError,
                          on_success=successes.append,
                          on_backoff=backoffs.append,
                          on_giveup=giveups.append,
                          max_tries=3,
                          jitter=None,
                          raise_on_giveup=raise_on_giveup,
                          interval=0)
    @_save_target
    def exceptor(*args, **kwargs):
        raise ValueError("catch me")

    if raise_on_giveup:
        with pytest.raises(ValueError):
            exceptor(1, 2, 3, foo=1, bar=2)
    else:
        exceptor(1, 2, 3, foo=1, bar=2)

    # we try 3 times, backing off twice and giving up once
    assert len(successes) == 0
    assert len(backoffs) == 2
    assert len(giveups) == 1

    details = giveups[0]
    elapsed = details.pop('elapsed')
    assert isinstance(elapsed, float)
    assert details == {'args': (1, 2, 3),
                       'kwargs': {'foo': 1, 'bar': 2},
                       'target': exceptor._target,
                       'tries': 3}


def test_on_exception_giveup_predicate(patch_time):

    def on_baz(e):
        return str(e) == "baz"

    vals = ["baz", "bar", "foo"]

    @backoff.on_exception(backoff.constant,
                          ValueError,
                          giveup=on_baz)
    def foo_bar_baz():
        raise ValueError(vals.pop())

    with pytest.raises(ValueError):
        foo_bar_baz()

    assert not vals


def test_on_predicate_success():
    backoffs, giveups, successes = [], [], []

    @backoff.on_predicate(backoff.constant,
                          on_success=successes.append,
                          on_backoff=backoffs.append,
                          on_giveup=giveups.append,
                          jitter=None,
                          interval=0)
    @_save_target
    def success(*args, **kwargs):
        # succeed after we've backed off twice
        return len(backoffs) == 2

    success(1, 2, 3, foo=1, bar=2)

    # we try 3 times, backing off twice before succeeding
    assert len(successes) == 1
    assert len(backoffs) == 2
    assert len(giveups) == 0

    for i in range(2):
        details = backoffs[i]

        elapsed = details.pop('elapsed')
        assert isinstance(elapsed, float)
        assert details == {'args': (1, 2, 3),
                           'kwargs': {'foo': 1, 'bar': 2},
                           'target': success._target,
                           'tries': i + 1,
                           'value': False,
                           'wait': 0}

    details = successes[0]
    elapsed = details.pop('elapsed')
    assert isinstance(elapsed, float)
    assert details == {'args': (1, 2, 3),
                       'kwargs': {'foo': 1, 'bar': 2},
                       'target': success._target,
                       'tries': 3,
                       'value': True}


def test_on_predicate_giveup():
    backoffs, giveups, successes = [], [], []

    @backoff.on_predicate(backoff.constant,
                          on_success=successes.append,
                          on_backoff=backoffs.append,
                          on_giveup=giveups.append,
                          max_tries=3,
                          jitter=None,
                          interval=0)
    @_save_target
    def emptiness(*args, **kwargs):
        pass

    emptiness(1, 2, 3, foo=1, bar=2)

    # we try 3 times, backing off twice and giving up once
    assert len(successes) == 0
    assert len(backoffs) == 2
    assert len(giveups) == 1

    details = giveups[0]
    elapsed = details.pop('elapsed')
    assert isinstance(elapsed, float)
    assert details == {'args': (1, 2, 3),
                       'kwargs': {'foo': 1, 'bar': 2},
                       'target': emptiness._target,
                       'tries': 3,
                       'value': None}


def test_on_predicate_iterable_handlers():
    class Logger:
        def __init__(self):
            self.backoffs = []
            self.giveups = []
            self.successes = []

    loggers = [Logger() for _ in range(3)]

    @backoff.on_predicate(backoff.constant,
                          on_backoff=(l.backoffs.append for l in loggers),
                          on_giveup=(l.giveups.append for l in loggers),
                          on_success=(l.successes.append for l in loggers),
                          max_tries=3,
                          jitter=None,
                          interval=0)
    @_save_target
    def emptiness(*args, **kwargs):
        pass

    emptiness(1, 2, 3, foo=1, bar=2)

    for logger in loggers:

        assert len(logger.successes) == 0
        assert len(logger.backoffs) == 2
        assert len(logger.giveups) == 1

        details = dict(logger.giveups[0])
        print(details)
        elapsed = details.pop('elapsed')
        assert isinstance(elapsed, float)
        assert details == {'args': (1, 2, 3),
                           'kwargs': {'foo': 1, 'bar': 2},
                           'target': emptiness._target,
                           'tries': 3,
                           'value': None}


# To maintain backward compatibility,
# on_predicate should support 0-argument jitter function.
def test_on_exception_success_0_arg_jitter(patch_time, monkeypatch):
    monkeypatch.setattr('random.random', lambda: 0)

    backoffs, giveups, successes = [], [], []

    @backoff.on_exception(backoff.constant,
                          Exception,
                          on_success=successes.append,
                          on_backoff=backoffs.append,
                          on_giveup=giveups.append,
                          jitter=random.random,
                          interval=0)
    @_save_target
    def succeeder(*args, **kwargs):
        # succeed after we've backed off twice
        if len(backoffs) < 2:
            raise ValueError("catch me")

    with pytest.deprecated_call():
        succeeder(1, 2, 3, foo=1, bar=2)

    # we try 3 times, backing off twice before succeeding
    assert len(successes) == 1
    assert len(backoffs) == 2
    assert len(giveups) == 0

    for i in range(2):
        details = backoffs[i]
        elapsed = details.pop('elapsed')
        assert isinstance(elapsed, float)
        assert details == {'args': (1, 2, 3),
                           'kwargs': {'foo': 1, 'bar': 2},
                           'target': succeeder._target,
                           'tries': i + 1,
                           'wait': 0}

    details = successes[0]
    elapsed = details.pop('elapsed')
    assert isinstance(elapsed, float)
    assert details == {'args': (1, 2, 3),
                       'kwargs': {'foo': 1, 'bar': 2},
                       'target': succeeder._target,
                       'tries': 3}


# To maintain backward compatibility,
# on_predicate should support 0-argument jitter function.
def test_on_predicate_success_0_arg_jitter(patch_time, monkeypatch):
    monkeypatch.setattr('random.random', lambda: 0)

    backoffs, giveups, successes = [], [], []

    @backoff.on_predicate(backoff.constant,
                          on_success=successes.append,
                          on_backoff=backoffs.append,
                          on_giveup=giveups.append,
                          jitter=random.random,
                          interval=0)
    @_save_target
    def success(*args, **kwargs):
        # succeed after we've backed off twice
        return len(backoffs) == 2

    with pytest.deprecated_call():
        success(1, 2, 3, foo=1, bar=2)

    # we try 3 times, backing off twice before succeeding
    assert len(successes) == 1
    assert len(backoffs) == 2
    assert len(giveups) == 0

    for i in range(2):
        details = backoffs[i]
        print(details)
        elapsed = details.pop('elapsed')
        assert isinstance(elapsed, float)
        assert details == {'args': (1, 2, 3),
                           'kwargs': {'foo': 1, 'bar': 2},
                           'target': success._target,
                           'tries': i + 1,
                           'value': False,
                           'wait': 0}

    details = successes[0]
    elapsed = details.pop('elapsed')
    assert isinstance(elapsed, float)
    assert details == {'args': (1, 2, 3),
                       'kwargs': {'foo': 1, 'bar': 2},
                       'target': success._target,
                       'tries': 3,
                       'value': True}


def test_on_exception_callable_max_tries(patch_time, monkeypatch):

    def lookup_max_tries():
        return 3

    log = []

    @backoff.on_exception(backoff.constant,
                          ValueError,
                          max_tries=lookup_max_tries)
    def exceptor():
        log.append(True)
        raise ValueError()

    with pytest.raises(ValueError):
        exceptor()

    assert len(log) == 3


def test_on_exception_callable_gen_kwargs():

    def lookup_foo():
        return "foo"

    def wait_gen(foo=None, bar=None):
        assert foo == "foo"
        assert bar == "bar"

        while True:
            yield 0

    @backoff.on_exception(wait_gen,
                          ValueError,
                          max_tries=2,
                          foo=lookup_foo,
                          bar="bar")
    def exceptor():
        raise ValueError("aah")

    with pytest.raises(ValueError):
        exceptor()


def test_on_predicate_in_thread(patch_time):

    result = []

    def check():
        try:
            @backoff.on_predicate(backoff.expo)
            def return_true(log, n):
                val = (len(log) == n - 1)
                log.append(val)
                return val

            log = []
            ret = return_true(log, 3)
            assert ret is True
            assert 3 == len(log)

        except Exception as ex:
            result.append(ex)
        else:
            result.append('success')

    t = threading.Thread(target=check)
    t.start()
    t.join()

    assert len(result) == 1
    assert result[0] == 'success'


def test_on_predicate_constant_iterable(patch_time):

    waits = [1, 2, 3, 6, 9]
    backoffs = []
    giveups = []
    successes = []

    @backoff.on_predicate(
        backoff.constant,
        interval=waits,
        on_backoff=backoffs.append,
        on_giveup=giveups.append,
        on_success=successes.append,
        jitter=None,
    )
    def falsey():
        return False

    assert not falsey()

    assert len(backoffs) == len(waits)
    for i, wait in enumerate(waits):
        assert backoffs[i]['wait'] == wait

    assert len(giveups) == 1
    assert len(successes) == 0


def test_on_exception_in_thread(patch_time):

    result = []

    def check():
        try:
            @backoff.on_exception(backoff.expo, KeyError)
            def keyerror_then_true(log, n):
                if len(log) == n:
                    return True
                e = KeyError()
                log.append(e)
                raise e

            log = []
            assert keyerror_then_true(log, 3) is True
            assert 3 == len(log)

        except Exception as ex:
            result.append(ex)
        else:
            result.append('success')

    t = threading.Thread(target=check)
    t.start()
    t.join()

    assert len(result) == 1
    assert result[0] == 'success'


def test_on_exception_logger_default(patch_time, caplog):

    logger = logging.getLogger('backoff')
    handler = logging.StreamHandler(sys.stdout)
    logger.addHandler(handler)

    @backoff.on_exception(backoff.expo, KeyError, max_tries=3)
    def key_error():
        raise KeyError()

    with caplog.at_level(logging.INFO):
        with pytest.raises(KeyError):
            key_error()

    assert len(caplog.records) == 3  # 2 backoffs and 1 giveup
    for record in caplog.records:
        assert record.name == 'backoff'


def test_on_exception_logger_none(patch_time, caplog):

    logger = logging.getLogger('backoff')
    handler = logging.StreamHandler(sys.stdout)
    logger.addHandler(handler)

    @backoff.on_exception(backoff.expo, KeyError, max_tries=3, logger=None)
    def key_error():
        raise KeyError()

    with caplog.at_level(logging.INFO):
        with pytest.raises(KeyError):
            key_error()

    assert not caplog.records


def test_on_exception_logger_user(patch_time, caplog):

    logger = logging.getLogger('my-logger')
    handler = logging.StreamHandler(sys.stdout)
    logger.addHandler(handler)

    @backoff.on_exception(backoff.expo, KeyError, max_tries=3, logger=logger)
    def key_error():
        raise KeyError()

    with caplog.at_level(logging.INFO):
        with pytest.raises(KeyError):
            key_error()

    assert len(caplog.records) == 3  # 2 backoffs and 1 giveup
    for record in caplog.records:
        assert record.name == 'my-logger'


def test_on_exception_logger_user_str(patch_time, caplog):

    logger = logging.getLogger('my-logger')
    handler = logging.StreamHandler(sys.stdout)
    logger.addHandler(handler)

    @backoff.on_exception(backoff.expo, KeyError, max_tries=3,
                          logger='my-logger')
    def key_error():
        raise KeyError()

    with caplog.at_level(logging.INFO):
        with pytest.raises(KeyError):
            key_error()

    assert len(caplog.records) == 3  # 2 backoffs and 1 giveup
    for record in caplog.records:
        assert record.name == 'my-logger'


def _on_exception_factory(
    backoff_log_level, giveup_log_level, max_tries
):
    @backoff.on_exception(
        backoff.expo,
        ValueError,
        max_tries=max_tries,
        backoff_log_level=backoff_log_level,
        giveup_log_level=giveup_log_level,
    )
    def value_error():
        raise ValueError

    def func():
        with pytest.raises(ValueError):
            value_error()

    return func


def _on_predicate_factory(
    backoff_log_level, giveup_log_level, max_tries
):
    @backoff.on_predicate(
        backoff.expo,
        max_tries=max_tries,
        backoff_log_level=backoff_log_level,
        giveup_log_level=giveup_log_level,
    )
    def func():
        return False

    return func


@pytest.mark.parametrize(
    ("func_factory", "backoff_log_level", "giveup_log_level"),
    (
        (factory, backoff_log_level, giveup_log_level)
        for backoff_log_level, giveup_log_level in itertools.product(
            (
                logging.DEBUG,
                logging.INFO,
                logging.WARNING,
                logging.ERROR,
                logging.CRITICAL,
            ),
            repeat=2,
        )
        for factory in (_on_predicate_factory, _on_exception_factory)
    )
)
def test_event_log_levels(
    caplog, func_factory, backoff_log_level, giveup_log_level
):
    max_tries = 3
    func = func_factory(backoff_log_level, giveup_log_level, max_tries)

    with unittest.mock.patch('time.sleep', return_value=None):
        with caplog.at_level(
            min(backoff_log_level, giveup_log_level), logger="backoff"
        ):
            func()

    backoff_re = re.compile("backing off", re.IGNORECASE)
    giveup_re = re.compile("giving up", re.IGNORECASE)

    backoff_log_count = 0
    giveup_log_count = 0
    for logger_name, level, message in caplog.record_tuples:
        if level == backoff_log_level and backoff_re.match(message):
            backoff_log_count += 1
        elif level == giveup_log_level and giveup_re.match(message):
            giveup_log_count += 1

    assert backoff_log_count == max_tries - 1
    assert giveup_log_count == 1
